Workbook

Sheet 勤務表
A1: 標準勤務表サンプル
A2: 祝日・会社休日を反映し、不足時間・残業・休日行を見える化するサンプルです。
A4: 対象年月 | B4: 46174
A5: 氏名 | B5: 山田 太郎
A6: 所定開始 | B6: 0.375
A7: 所定終了 | B7: 0.75
A9: 日付 | B9: 曜日 | C9: 休日判定 | D9: 勤務区分 | E9: 出勤 | F9: 退勤 | G9: 休憩 | H9: 勤務時間 | I9: 所定時間 | J9: 不足 | K9: 残業 | L9: 備考
A10: =IF(MONTH(DATE(YEAR($B$4),MONTH($B$4),1))<>MONTH($B$4),"",DATE(YEAR($B$4),MONTH($B$4),1)) -> 46174 | B10: =IF(A10="","",TEXT(A10,"aaa")) -> 月 | C10: =IF(A10="","",IF(COUNTIF(休日設定!$A$5:$A$80,A10)>0,"祝日",IF(COUNTIF(休日設定!$D$5:$D$80,A10)>0,"会社休日",IF(OR(B10="土",B10="日"),"土日","平日")))) -> 平日 | D10: =IF(A10="","",IF(C10="平日","出勤","休日")) -> 出勤 | E10: 0.375 | F10: 0.77083333 | G10: 0.041666667 | H10: =IF(OR(E10="",F10=""),"",MAX(0,F10-E10-G10)) -> 0.35416667 | I10: =IF(D10="出勤",TIME(8,0,0),IF(D10="半休",TIME(4,0,0),0)) -> 0.33333333 | J10: =IF(H10="","",MAX(0,I10-H10)) -> 0 | K10: =IF(H10="","",MAX(0,H10-I10)) -> 0.020833333
A11: =IF(MONTH(DATE(YEAR($B$4),MONTH($B$4),2))<>MONTH($B$4),"",DATE(YEAR($B$4),MONTH($B$4),2)) -> 46175 | B11: =IF(A11="","",TEXT(A11,"aaa")) -> 火 | C11: =IF(A11="","",IF(COUNTIF(休日設定!$A$5:$A$80,A11)>0,"祝日",IF(COUNTIF(休日設定!$D$5:$D$80,A11)>0,"会社休日",IF(OR(B11="土",B11="日"),"土日","平日")))) -> 平日 | D11: =IF(A11="","",IF(C11="平日","出勤","休日")) -> 出勤 | E11: 0.375 | F11: 0.77083333 | G11: 0.041666667 | H11: =IF(OR(E11="",F11=""),"",MAX(0,F11-E11-G11)) -> 0.35416667 | I11: =IF(D11="出勤",TIME(8,0,0),IF(D11="半休",TIME(4,0,0),0)) -> 0.33333333 | J11: =IF(H11="","",MAX(0,I11-H11)) -> 0 | K11: =IF(H11="","",MAX(0,H11-I11)) -> 0.020833333
A12: =IF(MONTH(DATE(YEAR($B$4),MONTH($B$4),3))<>MONTH($B$4),"",DATE(YEAR($B$4),MONTH($B$4),3)) -> 46176 | B12: =IF(A12="","",TEXT(A12,"aaa")) -> 水 | C12: =IF(A12="","",IF(COUNTIF(休日設定!$A$5:$A$80,A12)>0,"祝日",IF(COUNTIF(休日設定!$D$5:$D$80,A12)>0,"会社休日",IF(OR(B12="土",B12="日"),"土日","平日")))) -> 平日 | D12: =IF(A12="","",IF(C12="平日","出勤","休日")) -> 出勤 | E12: 0.39583333 | F12: 0.70833333 | G12: 0.041666667 | H12: =IF(OR(E12="",F12=""),"",MAX(0,F12-E12-G12)) -> 0.27083333 | I12: =IF(D12="出勤",TIME(8,0,0),IF(D12="半休",TIME(4,0,0),0)) -> 0.33333333 | J12: =IF(H12="","",MAX(0,I12-H12)) -> 0.0625 | K12: =IF(H12="","",MAX(0,H12-I12)) -> 0
A13: =IF(MONTH(DATE(YEAR($B$4),MONTH($B$4),4))<>MONTH($B$4),"",DATE(YEAR($B$4),MONTH($B$4),4)) -> 46177 | B13: =IF(A13="","",TEXT(A13,"aaa")) -> 木 | C13: =IF(A13="","",IF(COUNTIF(休日設定!$A$5:$A$80,A13)>0,"祝日",IF(COUNTIF(休日設定!$D$5:$D$80,A13)>0,"会社休日",IF(OR(B13="土",B13="日"),"土日","平日")))) -> 平日 | D13: =IF(A13="","",IF(C13="平日","出勤","休日")) -> 出勤 | E13: 0.375 | F13: 0.77083333 | G13: 0.041666667 | H13: =IF(OR(E13="",F13=""),"",MAX(0,F13-E13-G13)) -> 0.35416667 | I13: =IF(D13="出勤",TIME(8,0,0),IF(D13="半休",TIME(4,0,0),0)) -> 0.33333333 | J13: =IF(H13="","",MAX(0,I13-H13)) -> 0 | K13: =IF(H13="","",MAX(0,H13-I13)) -> 0.020833333
A14: =IF(MONTH(DATE(YEAR($B$4),MONTH($B$4),5))<>MONTH($B$4),"",DATE(YEAR($B$4),MONTH($B$4),5)) -> 46178 | B14: =IF(A14="","",TEXT(A14,"aaa")) -> 金 | C14: =IF(A14="","",IF(COUNTIF(休日設定!$A$5:$A$80,A14)>0,"祝日",IF(COUNTIF(休日設定!$D$5:$D$80,A14)>0,"会社休日",IF(OR(B14="土",B14="日"),"土日","平日")))) -> 平日 | D14: =IF(A14="","",IF(C14="平日","出勤","休日")) -> 出勤 | E14: 0.375 | F14: 0.77083333 | G14: 0.041666667 | H14: =IF(OR(E14="",F14=""),"",MAX(0,F14-E14-G14)) -> 0.35416667 | I14: =IF(D14="出勤",TIME(8,0,0),IF(D14="半休",TIME(4,0,0),0)) -> 0.33333333 | J14: =IF(H14="","",MAX(0,I14-H14)) -> 0 | K14: =IF(H14="","",MAX(0,H14-I14)) -> 0.020833333
A15: =IF(MONTH(DATE(YEAR($B$4),MONTH($B$4),6))<>MONTH($B$4),"",DATE(YEAR($B$4),MONTH($B$4),6)) -> 46179 | B15: =IF(A15="","",TEXT(A15,"aaa")) -> 土 | C15: =IF(A15="","",IF(COUNTIF(休日設定!$A$5:$A$80,A15)>0,"祝日",IF(COUNTIF(休日設定!$D$5:$D$80,A15)>0,"会社休日",IF(OR(B15="土",B15="日"),"土日","平日")))) -> 土日 | D15: =IF(A15="","",IF(C15="平日","出勤","休日")) -> 休日 | H15: =IF(OR(E15="",F15=""),"",MAX(0,F15-E15-G15)) | I15: =IF(D15="出勤",TIME(8,0,0),IF(D15="半休",TIME(4,0,0),0)) -> 0 | J15: =IF(H15="","",MAX(0,I15-H15)) | K15: =IF(H15="","",MAX(0,H15-I15))
A16: =IF(MONTH(DATE(YEAR($B$4),MONTH($B$4),7))<>MONTH($B$4),"",DATE(YEAR($B$4),MONTH($B$4),7)) -> 46180 | B16: =IF(A16="","",TEXT(A16,"aaa")) -> 日 | C16: =IF(A16="","",IF(COUNTIF(休日設定!$A$5:$A$80,A16)>0,"祝日",IF(COUNTIF(休日設定!$D$5:$D$80,A16)>0,"会社休日",IF(OR(B16="土",B16="日"),"土日","平日")))) -> 土日 | D16: =IF(A16="","",IF(C16="平日","出勤","休日")) -> 休日 | H16: =IF(OR(E16="",F16=""),"",MAX(0,F16-E16-G16)) | I16: =IF(D16="出勤",TIME(8,0,0),IF(D16="半休",TIME(4,0,0),0)) -> 0 | J16: =IF(H16="","",MAX(0,I16-H16)) | K16: =IF(H16="","",MAX(0,H16-I16))
A17: =IF(MONTH(DATE(YEAR($B$4),MONTH($B$4),8))<>MONTH($B$4),"",DATE(YEAR($B$4),MONTH($B$4),8)) -> 46181 | B17: =IF(A17="","",TEXT(A17,"aaa")) -> 月 | C17: =IF(A17="","",IF(COUNTIF(休日設定!$A$5:$A$80,A17)>0,"祝日",IF(COUNTIF(休日設定!$D$5:$D$80,A17)>0,"会社休日",IF(OR(B17="土",B17="日"),"土日","平日")))) -> 平日 | D17: =IF(A17="","",IF(C17="平日","出勤","休日")) -> 出勤 | H17: =IF(OR(E17="",F17=""),"",MAX(0,F17-E17-G17)) | I17: =IF(D17="出勤",TIME(8,0,0),IF(D17="半休",TIME(4,0,0),0)) -> 0.33333333 | J17: =IF(H17="","",MAX(0,I17-H17)) | K17: =IF(H17="","",MAX(0,H17-I17))
A18: =IF(MONTH(DATE(YEAR($B$4),MONTH($B$4),9))<>MONTH($B$4),"",DATE(YEAR($B$4),MONTH($B$4),9)) -> 46182 | B18: =IF(A18="","",TEXT(A18,"aaa")) -> 火 | C18: =IF(A18="","",IF(COUNTIF(休日設定!$A$5:$A$80,A18)>0,"祝日",IF(COUNTIF(休日設定!$D$5:$D$80,A18)>0,"会社休日",IF(OR(B18="土",B18="日"),"土日","平日")))) -> 平日 | D18: =IF(A18="","",IF(C18="平日","出勤","休日")) -> 出勤 | H18: =IF(OR(E18="",F18=""),"",MAX(0,F18-E18-G18)) | I18: =IF(D18="出勤",TIME(8,0,0),IF(D18="半休",TIME(4,0,0),0)) -> 0.33333333 | J18: =IF(H18="","",MAX(0,I18-H18)) | K18: =IF(H18="","",MAX(0,H18-I18))
A19: =IF(MONTH(DATE(YEAR($B$4),MONTH($B$4),10))<>MONTH($B$4),"",DATE(YEAR($B$4),MONTH($B$4),10)) -> 46183 | B19: =IF(A19="","",TEXT(A19,"aaa")) -> 水 | C19: =IF(A19="","",IF(COUNTIF(休日設定!$A$5:$A$80,A19)>0,"祝日",IF(COUNTIF(休日設定!$D$5:$D$80,A19)>0,"会社休日",IF(OR(B19="土",B19="日"),"土日","平日")))) -> 平日 | D19: =IF(A19="","",IF(C19="平日","出勤","休日")) -> 出勤 | H19: =IF(OR(E19="",F19=""),"",MAX(0,F19-E19-G19)) | I19: =IF(D19="出勤",TIME(8,0,0),IF(D19="半休",TIME(4,0,0),0)) -> 0.33333333 | J19: =IF(H19="","",MAX(0,I19-H19)) | K19: =IF(H19="","",MAX(0,H19-I19))
A20: =IF(MONTH(DATE(YEAR($B$4),MONTH($B$4),11))<>MONTH($B$4),"",DATE(YEAR($B$4),MONTH($B$4),11)) -> 46184 | B20: =IF(A20="","",TEXT(A20,"aaa")) -> 木 | C20: =IF(A20="","",IF(COUNTIF(休日設定!$A$5:$A$80,A20)>0,"祝日",IF(COUNTIF(休日設定!$D$5:$D$80,A20)>0,"会社休日",IF(OR(B20="土",B20="日"),"土日","平日")))) -> 平日 | D20: =IF(A20="","",IF(C20="平日","出勤","休日")) -> 出勤 | H20: =IF(OR(E20="",F20=""),"",MAX(0,F20-E20-G20)) | I20: =IF(D20="出勤",TIME(8,0,0),IF(D20="半休",TIME(4,0,0),0)) -> 0.33333333 | J20: =IF(H20="","",MAX(0,I20-H20)) | K20: =IF(H20="","",MAX(0,H20-I20))
A21: =IF(MONTH(DATE(YEAR($B$4),MONTH($B$4),12))<>MONTH($B$4),"",DATE(YEAR($B$4),MONTH($B$4),12)) -> 46185 | B21: =IF(A21="","",TEXT(A21,"aaa")) -> 金 | C21: =IF(A21="","",IF(COUNTIF(休日設定!$A$5:$A$80,A21)>0,"祝日",IF(COUNTIF(休日設定!$D$5:$D$80,A21)>0,"会社休日",IF(OR(B21="土",B21="日"),"土日","平日")))) -> 平日 | D21: =IF(A21="","",IF(C21="平日","出勤","休日")) -> 出勤 | H21: =IF(OR(E21="",F21=""),"",MAX(0,F21-E21-G21)) | I21: =IF(D21="出勤",TIME(8,0,0),IF(D21="半休",TIME(4,0,0),0)) -> 0.33333333 | J21: =IF(H21="","",MAX(0,I21-H21)) | K21: =IF(H21="","",MAX(0,H21-I21))
A22: =IF(MONTH(DATE(YEAR($B$4),MONTH($B$4),13))<>MONTH($B$4),"",DATE(YEAR($B$4),MONTH($B$4),13)) -> 46186 | B22: =IF(A22="","",TEXT(A22,"aaa")) -> 土 | C22: =IF(A22="","",IF(COUNTIF(休日設定!$A$5:$A$80,A22)>0,"祝日",IF(COUNTIF(休日設定!$D$5:$D$80,A22)>0,"会社休日",IF(OR(B22="土",B22="日"),"土日","平日")))) -> 土日 | D22: =IF(A22="","",IF(C22="平日","出勤","休日")) -> 休日 | H22: =IF(OR(E22="",F22=""),"",MAX(0,F22-E22-G22)) | I22: =IF(D22="出勤",TIME(8,0,0),IF(D22="半休",TIME(4,0,0),0)) -> 0 | J22: =IF(H22="","",MAX(0,I22-H22)) | K22: =IF(H22="","",MAX(0,H22-I22))
A23: =IF(MONTH(DATE(YEAR($B$4),MONTH($B$4),14))<>MONTH($B$4),"",DATE(YEAR($B$4),MONTH($B$4),14)) -> 46187 | B23: =IF(A23="","",TEXT(A23,"aaa")) -> 日 | C23: =IF(A23="","",IF(COUNTIF(休日設定!$A$5:$A$80,A23)>0,"祝日",IF(COUNTIF(休日設定!$D$5:$D$80,A23)>0,"会社休日",IF(OR(B23="土",B23="日"),"土日","平日")))) -> 土日 | D23: =IF(A23="","",IF(C23="平日","出勤","休日")) -> 休日 | H23: =IF(OR(E23="",F23=""),"",MAX(0,F23-E23-G23)) | I23: =IF(D23="出勤",TIME(8,0,0),IF(D23="半休",TIME(4,0,0),0)) -> 0 | J23: =IF(H23="","",MAX(0,I23-H23)) | K23: =IF(H23="","",MAX(0,H23-I23))
A24: =IF(MONTH(DATE(YEAR($B$4),MONTH($B$4),15))<>MONTH($B$4),"",DATE(YEAR($B$4),MONTH($B$4),15)) -> 46188 | B24: =IF(A24="","",TEXT(A24,"aaa")) -> 月 | C24: =IF(A24="","",IF(COUNTIF(休日設定!$A$5:$A$80,A24)>0,"祝日",IF(COUNTIF(休日設定!$D$5:$D$80,A24)>0,"会社休日",IF(OR(B24="土",B24="日"),"土日","平日")))) -> 会社休日 | D24: =IF(A24="","",IF(C24="平日","出勤","休日")) -> 休日 | H24: =IF(OR(E24="",F24=""),"",MAX(0,F24-E24-G24)) | I24: =IF(D24="出勤",TIME(8,0,0),IF(D24="半休",TIME(4,0,0),0)) -> 0 | J24: =IF(H24="","",MAX(0,I24-H24)) | K24: =IF(H24="","",MAX(0,H24-I24))
A25: =IF(MONTH(DATE(YEAR($B$4),MONTH($B$4),16))<>MONTH($B$4),"",DATE(YEAR($B$4),MONTH($B$4),16)) -> 46189 | B25: =IF(A25="","",TEXT(A25,"aaa")) -> 火 | C25: =IF(A25="","",IF(COUNTIF(休日設定!$A$5:$A$80,A25)>0,"祝日",IF(COUNTIF(休日設定!$D$5:$D$80,A25)>0,"会社休日",IF(OR(B25="土",B25="日"),"土日","平日")))) -> 平日 | D25: =IF(A25="","",IF(C25="平日","出勤","休日")) -> 出勤 | H25: =IF(OR(E25="",F25=""),"",MAX(0,F25-E25-G25)) | I25: =IF(D25="出勤",TIME(8,0,0),IF(D25="半休",TIME(4,0,0),0)) -> 0.33333333 | J25: =IF(H25="","",MAX(0,I25-H25)) | K25: =IF(H25="","",MAX(0,H25-I25))
A26: =IF(MONTH(DATE(YEAR($B$4),MONTH($B$4),17))<>MONTH($B$4),"",DATE(YEAR($B$4),MONTH($B$4),17)) -> 46190 | B26: =IF(A26="","",TEXT(A26,"aaa")) -> 水 | C26: =IF(A26="","",IF(COUNTIF(休日設定!$A$5:$A$80,A26)>0,"祝日",IF(COUNTIF(休日設定!$D$5:$D$80,A26)>0,"会社休日",IF(OR(B26="土",B26="日"),"土日","平日")))) -> 平日 | D26: =IF(A26="","",IF(C26="平日","出勤","休日")) -> 出勤 | H26: =IF(OR(E26="",F26=""),"",MAX(0,F26-E26-G26)) | I26: =IF(D26="出勤",TIME(8,0,0),IF(D26="半休",TIME(4,0,0),0)) -> 0.33333333 | J26: =IF(H26="","",MAX(0,I26-H26)) | K26: =IF(H26="","",MAX(0,H26-I26))
A27: =IF(MONTH(DATE(YEAR($B$4),MONTH($B$4),18))<>MONTH($B$4),"",DATE(YEAR($B$4),MONTH($B$4),18)) -> 46191 | B27: =IF(A27="","",TEXT(A27,"aaa")) -> 木 | C27: =IF(A27="","",IF(COUNTIF(休日設定!$A$5:$A$80,A27)>0,"祝日",IF(COUNTIF(休日設定!$D$5:$D$80,A27)>0,"会社休日",IF(OR(B27="土",B27="日"),"土日","平日")))) -> 平日 | D27: =IF(A27="","",IF(C27="平日","出勤","休日")) -> 出勤 | H27: =IF(OR(E27="",F27=""),"",MAX(0,F27-E27-G27)) | I27: =IF(D27="出勤",TIME(8,0,0),IF(D27="半休",TIME(4,0,0),0)) -> 0.33333333 | J27: =IF(H27="","",MAX(0,I27-H27)) | K27: =IF(H27="","",MAX(0,H27-I27))
A28: =IF(MONTH(DATE(YEAR($B$4),MONTH($B$4),19))<>MONTH($B$4),"",DATE(YEAR($B$4),MONTH($B$4),19)) -> 46192 | B28: =IF(A28="","",TEXT(A28,"aaa")) -> 金 | C28: =IF(A28="","",IF(COUNTIF(休日設定!$A$5:$A$80,A28)>0,"祝日",IF(COUNTIF(休日設定!$D$5:$D$80,A28)>0,"会社休日",IF(OR(B28="土",B28="日"),"土日","平日")))) -> 平日 | D28: =IF(A28="","",IF(C28="平日","出勤","休日")) -> 出勤 | H28: =IF(OR(E28="",F28=""),"",MAX(0,F28-E28-G28)) | I28: =IF(D28="出勤",TIME(8,0,0),IF(D28="半休",TIME(4,0,0),0)) -> 0.33333333 | J28: =IF(H28="","",MAX(0,I28-H28)) | K28: =IF(H28="","",MAX(0,H28-I28))
A29: =IF(MONTH(DATE(YEAR($B$4),MONTH($B$4),20))<>MONTH($B$4),"",DATE(YEAR($B$4),MONTH($B$4),20)) -> 46193 | B29: =IF(A29="","",TEXT(A29,"aaa")) -> 土 | C29: =IF(A29="","",IF(COUNTIF(休日設定!$A$5:$A$80,A29)>0,"祝日",IF(COUNTIF(休日設定!$D$5:$D$80,A29)>0,"会社休日",IF(OR(B29="土",B29="日"),"土日","平日")))) -> 土日 | D29: =IF(A29="","",IF(C29="平日","出勤","休日")) -> 休日 | H29: =IF(OR(E29="",F29=""),"",MAX(0,F29-E29-G29)) | I29: =IF(D29="出勤",TIME(8,0,0),IF(D29="半休",TIME(4,0,0),0)) -> 0 | J29: =IF(H29="","",MAX(0,I29-H29)) | K29: =IF(H29="","",MAX(0,H29-I29))
A30: =IF(MONTH(DATE(YEAR($B$4),MONTH($B$4),21))<>MONTH($B$4),"",DATE(YEAR($B$4),MONTH($B$4),21)) -> 46194 | B30: =IF(A30="","",TEXT(A30,"aaa")) -> 日 | C30: =IF(A30="","",IF(COUNTIF(休日設定!$A$5:$A$80,A30)>0,"祝日",IF(COUNTIF(休日設定!$D$5:$D$80,A30)>0,"会社休日",IF(OR(B30="土",B30="日"),"土日","平日")))) -> 土日 | D30: =IF(A30="","",IF(C30="平日","出勤","休日")) -> 休日 | H30: =IF(OR(E30="",F30=""),"",MAX(0,F30-E30-G30)) | I30: =IF(D30="出勤",TIME(8,0,0),IF(D30="半休",TIME(4,0,0),0)) -> 0 | J30: =IF(H30="","",MAX(0,I30-H30)) | K30: =IF(H30="","",MAX(0,H30-I30))
A31: =IF(MONTH(DATE(YEAR($B$4),MONTH($B$4),22))<>MONTH($B$4),"",DATE(YEAR($B$4),MONTH($B$4),22)) -> 46195 | B31: =IF(A31="","",TEXT(A31,"aaa")) -> 月 | C31: =IF(A31="","",IF(COUNTIF(休日設定!$A$5:$A$80,A31)>0,"祝日",IF(COUNTIF(休日設定!$D$5:$D$80,A31)>0,"会社休日",IF(OR(B31="土",B31="日"),"土日","平日")))) -> 平日 | D31: =IF(A31="","",IF(C31="平日","出勤","休日")) -> 出勤 | H31: =IF(OR(E31="",F31=""),"",MAX(0,F31-E31-G31)) | I31: =IF(D31="出勤",TIME(8,0,0),IF(D31="半休",TIME(4,0,0),0)) -> 0.33333333 | J31: =IF(H31="","",MAX(0,I31-H31)) | K31: =IF(H31="","",MAX(0,H31-I31))
A32: =IF(MONTH(DATE(YEAR($B$4),MONTH($B$4),23))<>MONTH($B$4),"",DATE(YEAR($B$4),MONTH($B$4),23)) -> 46196 | B32: =IF(A32="","",TEXT(A32,"aaa")) -> 火 | C32: =IF(A32="","",IF(COUNTIF(休日設定!$A$5:$A$80,A32)>0,"祝日",IF(COUNTIF(休日設定!$D$5:$D$80,A32)>0,"会社休日",IF(OR(B32="土",B32="日"),"土日","平日")))) -> 平日 | D32: =IF(A32="","",IF(C32="平日","出勤","休日")) -> 出勤 | H32: =IF(OR(E32="",F32=""),"",MAX(0,F32-E32-G32)) | I32: =IF(D32="出勤",TIME(8,0,0),IF(D32="半休",TIME(4,0,0),0)) -> 0.33333333 | J32: =IF(H32="","",MAX(0,I32-H32)) | K32: =IF(H32="","",MAX(0,H32-I32))
A33: =IF(MONTH(DATE(YEAR($B$4),MONTH($B$4),24))<>MONTH($B$4),"",DATE(YEAR($B$4),MONTH($B$4),24)) -> 46197 | B33: =IF(A33="","",TEXT(A33,"aaa")) -> 水 | C33: =IF(A33="","",IF(COUNTIF(休日設定!$A$5:$A$80,A33)>0,"祝日",IF(COUNTIF(休日設定!$D$5:$D$80,A33)>0,"会社休日",IF(OR(B33="土",B33="日"),"土日","平日")))) -> 平日 | D33: =IF(A33="","",IF(C33="平日","出勤","休日")) -> 出勤 | H33: =IF(OR(E33="",F33=""),"",MAX(0,F33-E33-G33)) | I33: =IF(D33="出勤",TIME(8,0,0),IF(D33="半休",TIME(4,0,0),0)) -> 0.33333333 | J33: =IF(H33="","",MAX(0,I33-H33)) | K33: =IF(H33="","",MAX(0,H33-I33))
A34: =IF(MONTH(DATE(YEAR($B$4),MONTH($B$4),25))<>MONTH($B$4),"",DATE(YEAR($B$4),MONTH($B$4),25)) -> 46198 | B34: =IF(A34="","",TEXT(A34,"aaa")) -> 木 | C34: =IF(A34="","",IF(COUNTIF(休日設定!$A$5:$A$80,A34)>0,"祝日",IF(COUNTIF(休日設定!$D$5:$D$80,A34)>0,"会社休日",IF(OR(B34="土",B34="日"),"土日","平日")))) -> 平日 | D34: =IF(A34="","",IF(C34="平日","出勤","休日")) -> 出勤 | H34: =IF(OR(E34="",F34=""),"",MAX(0,F34-E34-G34)) | I34: =IF(D34="出勤",TIME(8,0,0),IF(D34="半休",TIME(4,0,0),0)) -> 0.33333333 | J34: =IF(H34="","",MAX(0,I34-H34)) | K34: =IF(H34="","",MAX(0,H34-I34))
A35: =IF(MONTH(DATE(YEAR($B$4),MONTH($B$4),26))<>MONTH($B$4),"",DATE(YEAR($B$4),MONTH($B$4),26)) -> 46199 | B35: =IF(A35="","",TEXT(A35,"aaa")) -> 金 | C35: =IF(A35="","",IF(COUNTIF(休日設定!$A$5:$A$80,A35)>0,"祝日",IF(COUNTIF(休日設定!$D$5:$D$80,A35)>0,"会社休日",IF(OR(B35="土",B35="日"),"土日","平日")))) -> 平日 | D35: =IF(A35="","",IF(C35="平日","出勤","休日")) -> 出勤 | H35: =IF(OR(E35="",F35=""),"",MAX(0,F35-E35-G35)) | I35: =IF(D35="出勤",TIME(8,0,0),IF(D35="半休",TIME(4,0,0),0)) -> 0.33333333 | J35: =IF(H35="","",MAX(0,I35-H35)) | K35: =IF(H35="","",MAX(0,H35-I35))
A36: =IF(MONTH(DATE(YEAR($B$4),MONTH($B$4),27))<>MONTH($B$4),"",DATE(YEAR($B$4),MONTH($B$4),27)) -> 46200 | B36: =IF(A36="","",TEXT(A36,"aaa")) -> 土 | C36: =IF(A36="","",IF(COUNTIF(休日設定!$A$5:$A$80,A36)>0,"祝日",IF(COUNTIF(休日設定!$D$5:$D$80,A36)>0,"会社休日",IF(OR(B36="土",B36="日"),"土日","平日")))) -> 土日 | D36: =IF(A36="","",IF(C36="平日","出勤","休日")) -> 休日 | H36: =IF(OR(E36="",F36=""),"",MAX(0,F36-E36-G36)) | I36: =IF(D36="出勤",TIME(8,0,0),IF(D36="半休",TIME(4,0,0),0)) -> 0 | J36: =IF(H36="","",MAX(0,I36-H36)) | K36: =IF(H36="","",MAX(0,H36-I36))
A37: =IF(MONTH(DATE(YEAR($B$4),MONTH($B$4),28))<>MONTH($B$4),"",DATE(YEAR($B$4),MONTH($B$4),28)) -> 46201 | B37: =IF(A37="","",TEXT(A37,"aaa")) -> 日 | C37: =IF(A37="","",IF(COUNTIF(休日設定!$A$5:$A$80,A37)>0,"祝日",IF(COUNTIF(休日設定!$D$5:$D$80,A37)>0,"会社休日",IF(OR(B37="土",B37="日"),"土日","平日")))) -> 土日 | D37: =IF(A37="","",IF(C37="平日","出勤","休日")) -> 休日 | H37: =IF(OR(E37="",F37=""),"",MAX(0,F37-E37-G37)) | I37: =IF(D37="出勤",TIME(8,0,0),IF(D37="半休",TIME(4,0,0),0)) -> 0 | J37: =IF(H37="","",MAX(0,I37-H37)) | K37: =IF(H37="","",MAX(0,H37-I37))
A38: =IF(MONTH(DATE(YEAR($B$4),MONTH($B$4),29))<>MONTH($B$4),"",DATE(YEAR($B$4),MONTH($B$4),29)) -> 46202 | B38: =IF(A38="","",TEXT(A38,"aaa")) -> 月 | C38: =IF(A38="","",IF(COUNTIF(休日設定!$A$5:$A$80,A38)>0,"祝日",IF(COUNTIF(休日設定!$D$5:$D$80,A38)>0,"会社休日",IF(OR(B38="土",B38="日"),"土日","平日")))) -> 平日 | D38: =IF(A38="","",IF(C38="平日","出勤","休日")) -> 出勤 | H38: =IF(OR(E38="",F38=""),"",MAX(0,F38-E38-G38)) | I38: =IF(D38="出勤",TIME(8,0,0),IF(D38="半休",TIME(4,0,0),0)) -> 0.33333333 | J38: =IF(H38="","",MAX(0,I38-H38)) | K38: =IF(H38="","",MAX(0,H38-I38))
A39: =IF(MONTH(DATE(YEAR($B$4),MONTH($B$4),30))<>MONTH($B$4),"",DATE(YEAR($B$4),MONTH($B$4),30)) -> 46203 | B39: =IF(A39="","",TEXT(A39,"aaa")) -> 火 | C39: =IF(A39="","",IF(COUNTIF(休日設定!$A$5:$A$80,A39)>0,"祝日",IF(COUNTIF(休日設定!$D$5:$D$80,A39)>0,"会社休日",IF(OR(B39="土",B39="日"),"土日","平日")))) -> 平日 | D39: =IF(A39="","",IF(C39="平日","出勤","休日")) -> 出勤 | H39: =IF(OR(E39="",F39=""),"",MAX(0,F39-E39-G39)) | I39: =IF(D39="出勤",TIME(8,0,0),IF(D39="半休",TIME(4,0,0),0)) -> 0.33333333 | J39: =IF(H39="","",MAX(0,I39-H39)) | K39: =IF(H39="","",MAX(0,H39-I39))
A40: =IF(MONTH(DATE(YEAR($B$4),MONTH($B$4),31))<>MONTH($B$4),"",DATE(YEAR($B$4),MONTH($B$4),31)) | B40: =IF(A40="","",TEXT(A40,"aaa")) | C40: =IF(A40="","",IF(COUNTIF(休日設定!$A$5:$A$80,A40)>0,"祝日",IF(COUNTIF(休日設定!$D$5:$D$80,A40)>0,"会社休日",IF(OR(B40="土",B40="日"),"土日","平日")))) | D40: =IF(A40="","",IF(C40="平日","出勤","休日")) | H40: =IF(OR(E40="",F40=""),"",MAX(0,F40-E40-G40)) | I40: =IF(D40="出勤",TIME(8,0,0),IF(D40="半休",TIME(4,0,0),0)) -> 0 | J40: =IF(H40="","",MAX(0,I40-H40)) | K40: =IF(H40="","",MAX(0,H40-I40))
A43: 出勤日数 | B43: =COUNTIF(D10:D40,"出勤") -> 21
A44: 有休日数 | B44: =COUNTIF(D10:D40,"有休")+COUNTIF(D10:D40,"半休")*0.5 -> 0
...

Sheet 休日設定
A1: 休日設定
A2: 勤務表の休日判定に使う祝日・会社休日の一覧です。会社独自の休日は右側に追記できます。
A4: 祝日 | B4: 祝日名 | C4: メモ | D4: 会社休日 | E4: 休日名 | F4: メモ
A5: 46023 | B5: 元日 | D5: 46188 | E5: 創立記念日 | F5: 会社独自の休日サンプル
A6: 46034 | B6: 成人の日 | D6: 46247 | E6: 夏季休暇
A7: 46064 | B7: 建国記念の日 | D7: 46248 | E7: 夏季休暇
A8: 46076 | B8: 天皇誕生日 | D8: 46249 | E8: 夏季休暇
A9: 46101 | B9: 春分の日 | D9: 46385 | E9: 年末休暇
A10: 46141 | B10: 昭和の日 | D10: 46386 | E10: 年末休暇
A11: 46145 | B11: 憲法記念日 | D11: 46387 | E11: 年末休暇
A12: 46146 | B12: みどりの日
A13: 46147 | B13: こどもの日
A14: 46148 | B14: 振替休日
A15: 46223 | B15: 海の日
A16: 46245 | B16: 山の日
A17: 46286 | B17: 敬老の日
A18: 46287 | B18: 国民の休日
A19: 46288 | B19: 秋分の日
A20: 46307 | B20: スポーツの日
A21: 46329 | B21: 文化の日
A22: 46349 | B22: 勤労感謝の日
